[2023-09-11T02:13:23.870+0000] {taskinstance.py:1157} INFO - Dependencies all met for dep_context=non-requeueable deps ti=<TaskInstance: stock_data_pipeline.check_table_existence manual__2023-09-11T02:08:15.743580+00:00 [queued]>
[2023-09-11T02:13:23.876+0000] {taskinstance.py:1157} INFO - Dependencies all met for dep_context=requeueable deps ti=<TaskInstance: stock_data_pipeline.check_table_existence manual__2023-09-11T02:08:15.743580+00:00 [queued]>
[2023-09-11T02:13:23.877+0000] {taskinstance.py:1359} INFO - Starting attempt 2 of 2
[2023-09-11T02:13:23.885+0000] {taskinstance.py:1380} INFO - Executing <Task(BranchPythonOperator): check_table_existence> on 2023-09-11 02:08:15.743580+00:00
[2023-09-11T02:13:23.891+0000] {standard_task_runner.py:57} INFO - Started process 177 to run task
[2023-09-11T02:13:23.894+0000] {standard_task_runner.py:84} INFO - Running: ['***', 'tasks', 'run', 'stock_data_pipeline', 'check_table_existence', 'manual__2023-09-11T02:08:15.743580+00:00', '--job-id', '5', '--raw', '--subdir', 'DAGS_FOLDER/main_dag.py', '--cfg-path', '/tmp/tmpoyrugtwn']
[2023-09-11T02:13:23.898+0000] {standard_task_runner.py:85} INFO - Job 5: Subtask check_table_existence
[2023-09-11T02:13:23.940+0000] {task_command.py:415} INFO - Running <TaskInstance: stock_data_pipeline.check_table_existence manual__2023-09-11T02:08:15.743580+00:00 [running]> on host 8286c28131ea
[2023-09-11T02:13:24.299+0000] {taskinstance.py:1660} INFO - Exporting env vars: AIRFLOW_CTX_DAG_OWNER='you' AIRFLOW_CTX_DAG_ID='stock_data_pipeline' AIRFLOW_CTX_TASK_ID='check_table_existence' AIRFLOW_CTX_EXECUTION_DATE='2023-09-11T02:08:15.743580+00:00' AIRFLOW_CTX_TRY_NUMBER='2' AIRFLOW_CTX_DAG_RUN_ID='manual__2023-09-11T02:08:15.743580+00:00'
[2023-09-11T02:13:24.301+0000] {taskinstance.py:1935} ERROR - Task failed with exception
Traceback (most recent call last):
  File "/home/airflow/.local/lib/python3.8/site-packages/airflow/operators/python.py", line 226, in execute
    branch = super().execute(context)
  File "/home/airflow/.local/lib/python3.8/site-packages/airflow/operators/python.py", line 192, in execute
    return_value = self.execute_callable()
  File "/home/airflow/.local/lib/python3.8/site-packages/airflow/operators/python.py", line 209, in execute_callable
    return self.python_callable(*self.op_args, **self.op_kwargs)
  File "/opt/airflow/dags/main_dag.py", line 111, in check_table_existence
    conn = get_db_connection()
  File "/opt/airflow/dags/main_dag.py", line 97, in get_db_connection
    return psycopg2.connect(host="localhost", dbname="airflow", user="airflow", password="airflow")
  File "/home/airflow/.local/lib/python3.8/site-packages/psycopg2/__init__.py", line 122, in connect
    conn = _connect(dsn, connection_factory=connection_factory, **kwasync)
psycopg2.OperationalError: connection to server at "localhost" (127.0.0.1), port 5432 failed: Connection refused
	Is the server running on that host and accepting TCP/IP connections?
connection to server at "localhost" (::1), port 5432 failed: Cannot assign requested address
	Is the server running on that host and accepting TCP/IP connections?

[2023-09-11T02:13:24.313+0000] {taskinstance.py:1398} INFO - Marking task as FAILED. dag_id=stock_data_pipeline, task_id=check_table_existence, execution_date=20230911T020815, start_date=20230911T021323, end_date=20230911T021324
[2023-09-11T02:13:24.321+0000] {standard_task_runner.py:104} ERROR - Failed to execute job 5 for task check_table_existence (connection to server at "localhost" (127.0.0.1), port 5432 failed: Connection refused
	Is the server running on that host and accepting TCP/IP connections?
connection to server at "localhost" (::1), port 5432 failed: Cannot assign requested address
	Is the server running on that host and accepting TCP/IP connections?
; 177)
[2023-09-11T02:13:24.353+0000] {local_task_job_runner.py:228} INFO - Task exited with return code 1
[2023-09-11T02:13:24.379+0000] {taskinstance.py:2776} INFO - 0 downstream tasks scheduled from follow-on schedule check
